<?xml version="1.0" ?>
<!-- =================================================================================== -->
<!-- |    This document was autogenerated by xacro from manipulator.xacro              | -->
<!-- |    EDITING THIS FILE BY HAND IS NOT RECOMMENDED                                 | -->
<!-- =================================================================================== -->
<robot name="manipulator">
  <material name="silver">
    <color rgba="0.700 0.700 0.700 1.000"/>
  </material>
  <transmission name="ÈžÀü 48_tran">
    <type>transmission_interface/SimpleTransmission</type>
    <joint name="ÈžÀü 48">
      <hardwareInterface>hardware_interface/EffortJointInterface</hardwareInterface>
    </joint>
    <actuator name="ÈžÀü 48_actr">
      <hardwareInterface>hardware_interface/EffortJointInterface</hardwareInterface>
      <mechanicalReduction>1</mechanicalReduction>
    </actuator>
  </transmission>
  <transmission name="ÈžÀü 50_tran">
    <type>transmission_interface/SimpleTransmission</type>
    <joint name="ÈžÀü 50">
      <hardwareInterface>hardware_interface/EffortJointInterface</hardwareInterface>
    </joint>
    <actuator name="ÈžÀü 50_actr">
      <hardwareInterface>hardware_interface/EffortJointInterface</hardwareInterface>
      <mechanicalReduction>1</mechanicalReduction>
    </actuator>
  </transmission>
  <transmission name="ÈžÀü 52_tran">
    <type>transmission_interface/SimpleTransmission</type>
    <joint name="ÈžÀü 52">
      <hardwareInterface>hardware_interface/EffortJointInterface</hardwareInterface>
    </joint>
    <actuator name="ÈžÀü 52_actr">
      <hardwareInterface>hardware_interface/EffortJointInterface</hardwareInterface>
      <mechanicalReduction>1</mechanicalReduction>
    </actuator>
  </transmission>
  <transmission name="ÈžÀü 54_tran">
    <type>transmission_interface/SimpleTransmission</type>
    <joint name="ÈžÀü 54">
      <hardwareInterface>hardware_interface/EffortJointInterface</hardwareInterface>
    </joint>
    <actuator name="ÈžÀü 54_actr">
      <hardwareInterface>hardware_interface/EffortJointInterface</hardwareInterface>
      <mechanicalReduction>1</mechanicalReduction>
    </actuator>
  </transmission>
  <transmission name="ÈžÀü 56_tran">
    <type>transmission_interface/SimpleTransmission</type>
    <joint name="ÈžÀü 56">
      <hardwareInterface>hardware_interface/EffortJointInterface</hardwareInterface>
    </joint>
    <actuator name="ÈžÀü 56_actr">
      <hardwareInterface>hardware_interface/EffortJointInterface</hardwareInterface>
      <mechanicalReduction>1</mechanicalReduction>
    </actuator>
  </transmission>
  <transmission name="ÈžÀü 59_tran">
    <type>transmission_interface/SimpleTransmission</type>
    <joint name="ÈžÀü 59">
      <hardwareInterface>hardware_interface/EffortJointInterface</hardwareInterface>
    </joint>
    <actuator name="ÈžÀü 59_actr">
      <hardwareInterface>hardware_interface/EffortJointInterface</hardwareInterface>
      <mechanicalReduction>1</mechanicalReduction>
    </actuator>
  </transmission>
  <gazebo>
    <plugin filename="libgazebo_ros_control.so" name="control"/>
  </gazebo>
  <gazebo reference="base_link">
    <material>Gazebo/Silver</material>
    <mu1>0.2</mu1>
    <mu2>0.2</mu2>
    <selfCollide>true</selfCollide>
    <gravity>true</gravity>
  </gazebo>
  <gazebo reference="case1_1">
    <material>Gazebo/Silver</material>
    <mu1>0.2</mu1>
    <mu2>0.2</mu2>
    <selfCollide>true</selfCollide>
  </gazebo>
  <gazebo reference="base2_1">
    <material>Gazebo/Silver</material>
    <mu1>0.2</mu1>
    <mu2>0.2</mu2>
    <selfCollide>true</selfCollide>
  </gazebo>
  <gazebo reference="link1_1">
    <material>Gazebo/Silver</material>
    <mu1>0.2</mu1>
    <mu2>0.2</mu2>
    <selfCollide>true</selfCollide>
  </gazebo>
  <gazebo reference="case2_1">
    <material>Gazebo/Silver</material>
    <mu1>0.2</mu1>
    <mu2>0.2</mu2>
    <selfCollide>true</selfCollide>
  </gazebo>
  <gazebo reference="link2_1">
    <material>Gazebo/Silver</material>
    <mu1>0.2</mu1>
    <mu2>0.2</mu2>
    <selfCollide>true</selfCollide>
  </gazebo>
  <gazebo reference="case3_1">
    <material>Gazebo/Silver</material>
    <mu1>0.2</mu1>
    <mu2>0.2</mu2>
    <selfCollide>true</selfCollide>
  </gazebo>
  <gazebo reference="link3_1">
    <material>Gazebo/Silver</material>
    <mu1>0.2</mu1>
    <mu2>0.2</mu2>
    <selfCollide>true</selfCollide>
  </gazebo>
  <gazebo reference="case4_1">
    <material>Gazebo/Silver</material>
    <mu1>0.2</mu1>
    <mu2>0.2</mu2>
    <selfCollide>true</selfCollide>
  </gazebo>
  <gazebo reference="link4_1">
    <material>Gazebo/Silver</material>
    <mu1>0.2</mu1>
    <mu2>0.2</mu2>
    <selfCollide>true</selfCollide>
  </gazebo>
  <gazebo reference="case5_1">
    <material>Gazebo/Silver</material>
    <mu1>0.2</mu1>
    <mu2>0.2</mu2>
    <selfCollide>true</selfCollide>
  </gazebo>
  <gazebo reference="link5_1">
    <material>Gazebo/Silver</material>
    <mu1>0.2</mu1>
    <mu2>0.2</mu2>
    <selfCollide>true</selfCollide>
  </gazebo>
  <gazebo reference="case6_1">
    <material>Gazebo/Silver</material>
    <mu1>0.2</mu1>
    <mu2>0.2</mu2>
    <selfCollide>true</selfCollide>
  </gazebo>
  <gazebo reference="link6_1">
    <material>Gazebo/Silver</material>
    <mu1>0.2</mu1>
    <mu2>0.2</mu2>
    <selfCollide>true</selfCollide>
  </gazebo>
  <gazebo reference="link7_1">
    <material>Gazebo/Silver</material>
    <mu1>0.2</mu1>
    <mu2>0.2</mu2>
    <selfCollide>true</selfCollide>
  </gazebo>
  <link name="base_link">
    <inertial>
      <origin rpy="0 0 0" xyz="0.02239590734911897 -0.01176063731820371 -0.05451857845527507"/>
      <mass value="0.408609033804223"/>
      <inertia ixx="0.001136" ixy="0.0" ixz="8.9e-05" iyy="0.000464" iyz="-1e-06" izz="0.000843"/>
    </inertial>
    <visual>
      <origin rpy="0 0 0" xyz="0 0 0"/>
      <geometry>
        <mesh filename="package://manipulator/meshes/base_link.stl" scale="0.001 0.001 0.001"/>
      </geometry>
      <material name="silver"/>
    </visual>
    <collision>
      <origin rpy="0 0 0" xyz="0 0 0"/>
      <geometry>
        <mesh filename="package://manipulator/meshes/base_link.stl" scale="0.001 0.001 0.001"/>
      </geometry>
    </collision>
  </link>
  <link name="case1_1">
    <inertial>
      <origin rpy="0 0 0" xyz="-0.014250070484127172 0.01640828355791238 -0.005433634059177349"/>
      <mass value="0.34080653415518675"/>
      <inertia ixx="9.4e-05" ixy="-0.0" ixz="-0.0" iyy="5.5e-05" iyz="0.0" izz="8.2e-05"/>
    </inertial>
    <visual>
      <origin rpy="0 0 0" xyz="-0.012868 0.027801 -0.001527"/>
      <geometry>
        <mesh filename="package://manipulator/meshes/case1_1.stl" scale="0.001 0.001 0.001"/>
      </geometry>
      <material name="silver"/>
    </visual>
    <collision>
      <origin rpy="0 0 0" xyz="-0.012868 0.027801 -0.001527"/>
      <geometry>
        <mesh filename="package://manipulator/meshes/case1_1.stl" scale="0.001 0.001 0.001"/>
      </geometry>
    </collision>
  </link>
  <link name="base2_1">
    <inertial>
      <origin rpy="0 0 0" xyz="-0.009528048317381948 0.016040362681779042 -0.056045578455275115"/>
      <mass value="0.4086090338042252"/>
      <inertia ixx="0.001136" ixy="-0.0" ixz="-8.9e-05" iyy="0.000464" iyz="-1e-06" izz="0.000843"/>
    </inertial>
    <visual>
      <origin rpy="0 0 0" xyz="0.015632 0.027801 -0.001527"/>
      <geometry>
        <mesh filename="package://manipulator/meshes/base2_1.stl" scale="0.001 0.001 0.001"/>
      </geometry>
      <material name="silver"/>
    </visual>
    <collision>
      <origin rpy="0 0 0" xyz="0.015632 0.027801 -0.001527"/>
      <geometry>
        <mesh filename="package://manipulator/meshes/base2_1.stl" scale="0.001 0.001 0.001"/>
      </geometry>
    </collision>
  </link>
  <link name="link1_1">
    <inertial>
      <origin rpy="0 0 0" xyz="0.00041157170309191976 -1.4624828903732844e-07 0.0450438228157928"/>
      <mass value="0.2016099043724989"/>
      <inertia ixx="0.000258" ixy="-0.0" ixz="-2e-06" iyy="0.00023" iyz="-0.0" izz="6.9e-05"/>
    </inertial>
    <visual>
      <origin rpy="0 0 0" xyz="0.001382 -0.000199 -0.014527"/>
      <geometry>
        <mesh filename="package://manipulator/meshes/link1_1.stl" scale="0.001 0.001 0.001"/>
      </geometry>
      <material name="silver"/>
    </visual>
    <collision>
      <origin rpy="0 0 0" xyz="0.001382 -0.000199 -0.014527"/>
      <geometry>
        <mesh filename="package://manipulator/meshes/link1_1.stl" scale="0.001 0.001 0.001"/>
      </geometry>
    </collision>
  </link>
  <link name="case2_1">
    <inertial>
      <origin rpy="0 0 0" xyz="0.006566487292350457 0.014249853751715245 0.01640823797054204"/>
      <mass value="0.34080653415518675"/>
      <inertia ixx="8.2e-05" ixy="-0.0" ixz="0.0" iyy="9.4e-05" iyz="-0.0" izz="5.5e-05"/>
    </inertial>
    <visual>
      <origin rpy="0 0 0" xyz="0.007382 0.014051 -0.075277"/>
      <geometry>
        <mesh filename="package://manipulator/meshes/case2_1.stl" scale="0.001 0.001 0.001"/>
      </geometry>
      <material name="silver"/>
    </visual>
    <collision>
      <origin rpy="0 0 0" xyz="0.007382 0.014051 -0.075277"/>
      <geometry>
        <mesh filename="package://manipulator/meshes/case2_1.stl" scale="0.001 0.001 0.001"/>
      </geometry>
    </collision>
  </link>
  <link name="link2_1">
    <inertial>
      <origin rpy="0 0 0" xyz="-0.004213732758277829 -1.462482890274351e-07 0.05761392703177749"/>
      <mass value="0.18470002339388275"/>
      <inertia ixx="0.000144" ixy="0.0" ixz="-6.7e-05" iyy="0.000231" iyz="0.0" izz="0.000104"/>
    </inertial>
    <visual>
      <origin rpy="0 0 0" xyz="-0.017618 -0.000199 -0.103277"/>
      <geometry>
        <mesh filename="package://manipulator/meshes/link2_1.stl" scale="0.001 0.001 0.001"/>
      </geometry>
      <material name="silver"/>
    </visual>
    <collision>
      <origin rpy="0 0 0" xyz="-0.017618 -0.000199 -0.103277"/>
      <geometry>
        <mesh filename="package://manipulator/meshes/link2_1.stl" scale="0.001 0.001 0.001"/>
      </geometry>
    </collision>
  </link>
  <link name="case3_1">
    <inertial>
      <origin rpy="0 0 0" xyz="0.005433371739386662 0.00799985375170667 0.023658237970542173"/>
      <mass value="0.34080653415518675"/>
      <inertia ixx="8.2e-05" ixy="-0.0" ixz="-0.0" iyy="9.4e-05" iyz="0.0" izz="5.5e-05"/>
    </inertial>
    <visual>
      <origin rpy="0 0 0" xyz="-0.030618 0.007801 -0.198927"/>
      <geometry>
        <mesh filename="package://manipulator/meshes/case3_1.stl" scale="0.001 0.001 0.001"/>
      </geometry>
      <material name="silver"/>
    </visual>
    <collision>
      <origin rpy="0 0 0" xyz="-0.030618 0.007801 -0.198927"/>
      <geometry>
        <mesh filename="package://manipulator/meshes/case3_1.stl" scale="0.001 0.001 0.001"/>
      </geometry>
    </collision>
  </link>
  <link name="link3_1">
    <inertial>
      <origin rpy="0 0 0" xyz="0.0016650787321817323 -1.4624828901480414e-07 0.05671011320901989"/>
      <mass value="0.25106312786468626"/>
      <inertia ixx="0.000153" ixy="-0.0" ixz="6.5e-05" iyy="0.000286" iyz="0.0" izz="0.000215"/>
    </inertial>
    <visual>
      <origin rpy="0 0 0" xyz="-0.017618 -0.000199 -0.234177"/>
      <geometry>
        <mesh filename="package://manipulator/meshes/link3_1.stl" scale="0.001 0.001 0.001"/>
      </geometry>
      <material name="silver"/>
    </visual>
    <collision>
      <origin rpy="0 0 0" xyz="-0.017618 -0.000199 -0.234177"/>
      <geometry>
        <mesh filename="package://manipulator/meshes/link3_1.stl" scale="0.001 0.001 0.001"/>
      </geometry>
    </collision>
  </link>
  <link name="case4_1">
    <inertial>
      <origin rpy="0 0 0" xyz="0.01640835932206992 0.014249853751706763 -0.005433634059177295"/>
      <mass value="0.34080653415518675"/>
      <inertia ixx="5.5e-05" ixy="0.0" ixz="0.0" iyy="9.4e-05" iyz="0.0" izz="8.2e-05"/>
    </inertial>
    <visual>
      <origin rpy="0 0 0" xyz="0.029382 0.014051 -0.313327"/>
      <geometry>
        <mesh filename="package://manipulator/meshes/case4_1.stl" scale="0.001 0.001 0.001"/>
      </geometry>
      <material name="silver"/>
    </visual>
    <collision>
      <origin rpy="0 0 0" xyz="0.029382 0.014051 -0.313327"/>
      <geometry>
        <mesh filename="package://manipulator/meshes/case4_1.stl" scale="0.001 0.001 0.001"/>
      </geometry>
    </collision>
  </link>
  <link name="link4_1">
    <inertial>
      <origin rpy="0 0 0" xyz="0.00041157170309193483 -1.4624828901919516e-07 0.04504382281579289"/>
      <mass value="0.2016099043724985"/>
      <inertia ixx="0.000258" ixy="-0.0" ixz="-2e-06" iyy="0.00023" iyz="0.0" izz="6.9e-05"/>
    </inertial>
    <visual>
      <origin rpy="0 0 0" xyz="0.001382 -0.000199 -0.326327"/>
      <geometry>
        <mesh filename="package://manipulator/meshes/link4_1.stl" scale="0.001 0.001 0.001"/>
      </geometry>
      <material name="silver"/>
    </visual>
    <collision>
      <origin rpy="0 0 0" xyz="0.001382 -0.000199 -0.326327"/>
      <geometry>
        <mesh filename="package://manipulator/meshes/link4_1.stl" scale="0.001 0.001 0.001"/>
      </geometry>
    </collision>
  </link>
  <link name="case5_1">
    <inertial>
      <origin rpy="0 0 0" xyz="-0.005433512707649504 -0.014250146248284797 -0.0075917620294578825"/>
      <mass value="0.34080653415518675"/>
      <inertia ixx="8.2e-05" ixy="-0.0" ixz="0.0" iyy="9.4e-05" iyz="-0.0" izz="5.5e-05"/>
    </inertial>
    <visual>
      <origin rpy="0 0 0" xyz="-0.004618 -0.014449 -0.411077"/>
      <geometry>
        <mesh filename="package://manipulator/meshes/case5_1.stl" scale="0.001 0.001 0.001"/>
      </geometry>
      <material name="silver"/>
    </visual>
    <collision>
      <origin rpy="0 0 0" xyz="-0.004618 -0.014449 -0.411077"/>
      <geometry>
        <mesh filename="package://manipulator/meshes/case5_1.stl" scale="0.001 0.001 0.001"/>
      </geometry>
    </collision>
  </link>
  <link name="link5_1">
    <inertial>
      <origin rpy="0 0 0" xyz="-0.007731817816433031 -0.00025506341510029255 0.0424196457662081"/>
      <mass value="0.1643237934541035"/>
      <inertia ixx="8.1e-05" ixy="0.0" ixz="-2.4e-05" iyy="0.000131" iyz="1e-06" izz="8.1e-05"/>
    </inertial>
    <visual>
      <origin rpy="0 0 0" xyz="-0.017618 -0.000199 -0.415077"/>
      <geometry>
        <mesh filename="package://manipulator/meshes/link5_1.stl" scale="0.001 0.001 0.001"/>
      </geometry>
      <material name="silver"/>
    </visual>
    <collision>
      <origin rpy="0 0 0" xyz="-0.017618 -0.000199 -0.415077"/>
      <geometry>
        <mesh filename="package://manipulator/meshes/link5_1.stl" scale="0.001 0.001 0.001"/>
      </geometry>
    </collision>
  </link>
  <link name="case6_1">
    <inertial>
      <origin rpy="0 0 0" xyz="-0.008000070484127209 -0.006566704024770846 0.023658237970542118"/>
      <mass value="0.34080653415518675"/>
      <inertia ixx="9.4e-05" ixy="0.0" ixz="-0.0" iyy="8.2e-05" iyz="-0.0" izz="5.5e-05"/>
    </inertial>
    <visual>
      <origin rpy="0 0 0" xyz="-0.043868 -0.006199 -0.460727"/>
      <geometry>
        <mesh filename="package://manipulator/meshes/case6_1.stl" scale="0.001 0.001 0.001"/>
      </geometry>
      <material name="silver"/>
    </visual>
    <collision>
      <origin rpy="0 0 0" xyz="-0.043868 -0.006199 -0.460727"/>
      <geometry>
        <mesh filename="package://manipulator/meshes/case6_1.stl" scale="0.001 0.001 0.001"/>
      </geometry>
    </collision>
  </link>
  <link name="link6_1">
    <inertial>
      <origin rpy="0 0 0" xyz="0.003970831683360154 -0.006329811420383323 0.03690785967114296"/>
      <mass value="0.25174373584366844"/>
      <inertia ixx="0.000389" ixy="0.0" ixz="-0.0" iyy="0.000354" iyz="-4e-06" izz="3.8e-05"/>
    </inertial>
    <visual>
      <origin rpy="0 0 0" xyz="-0.050118 -0.006199 -0.491977"/>
      <geometry>
        <mesh filename="package://manipulator/meshes/link6_1.stl" scale="0.001 0.001 0.001"/>
      </geometry>
      <material name="silver"/>
    </visual>
    <collision>
      <origin rpy="0 0 0" xyz="-0.050118 -0.006199 -0.491977"/>
      <geometry>
        <mesh filename="package://manipulator/meshes/link6_1.stl" scale="0.001 0.001 0.001"/>
      </geometry>
    </collision>
  </link>
  <link name="link7_1">
    <inertial>
      <origin rpy="0 0 0" xyz="-0.023072508481003125 0.018999853751710906 0.05456040638673598"/>
      <mass value="0.15138355095135578"/>
      <inertia ixx="0.000171" ixy="-0.0" ixz="2e-05" iyy="0.00014" iyz="-0.0" izz="4.5e-05"/>
    </inertial>
    <visual>
      <origin rpy="0 0 0" xyz="-0.035868 0.018801 -0.495977"/>
      <geometry>
        <mesh filename="package://manipulator/meshes/link7_1.stl" scale="0.001 0.001 0.001"/>
      </geometry>
      <material name="silver"/>
    </visual>
    <collision>
      <origin rpy="0 0 0" xyz="-0.035868 0.018801 -0.495977"/>
      <geometry>
        <mesh filename="package://manipulator/meshes/link7_1.stl" scale="0.001 0.001 0.001"/>
      </geometry>
    </collision>
  </link>
  <joint name="°­ÃŒ 46" type="fixed">
    <origin rpy="0 0 0" xyz="0.012868 -0.027801 0.001527"/>
    <parent link="base_link"/>
    <child link="case1_1"/>
  </joint>
  <joint name="°­ÃŒ 47" type="fixed">
    <origin rpy="0 0 0" xyz="-0.0285 0.0 0.0"/>
    <parent link="case1_1"/>
    <child link="base2_1"/>
  </joint>
  <joint name="ÈžÀü 48" type="continuous">
    <origin rpy="0 0 0" xyz="-0.01425 0.028 0.013"/>
    <parent link="case1_1"/>
    <child link="link1_1"/>
    <axis xyz="0.0 0.0 1.0"/>
  </joint>
  <joint name="°­ÃŒ 49" type="fixed">
    <origin rpy="0 0 0" xyz="-0.006 -0.01425 0.06075"/>
    <parent link="link1_1"/>
    <child link="case2_1"/>
  </joint>
  <joint name="ÈžÀü 50" type="continuous">
    <origin rpy="0 0 0" xyz="0.025 0.01425 0.028"/>
    <parent link="case2_1"/>
    <child link="link2_1"/>
    <axis xyz="1.0 -0.0 -0.0"/>
  </joint>
  <joint name="°­ÃŒ 51" type="fixed">
    <origin rpy="0 0 0" xyz="0.013 -0.008 0.09565"/>
    <parent link="link2_1"/>
    <child link="case3_1"/>
  </joint>
  <joint name="ÈžÀü 52" type="continuous">
    <origin rpy="0 0 0" xyz="-0.013 0.008 0.03525"/>
    <parent link="case3_1"/>
    <child link="link3_1"/>
    <axis xyz="-1.0 0.0 0.0"/>
  </joint>
  <joint name="°­ÃŒ 53" type="fixed">
    <origin rpy="0 0 0" xyz="-0.047 -0.01425 0.07915"/>
    <parent link="link3_1"/>
    <child link="case4_1"/>
  </joint>
  <joint name="ÈžÀü 54" type="continuous">
    <origin rpy="0 0 0" xyz="0.028 0.01425 0.013"/>
    <parent link="case4_1"/>
    <child link="link4_1"/>
    <axis xyz="0.0 0.0 1.0"/>
  </joint>
  <joint name="°­ÃŒ 55" type="fixed">
    <origin rpy="0 0 0" xyz="0.006 0.01425 0.08475"/>
    <parent link="link4_1"/>
    <child link="case5_1"/>
  </joint>
  <joint name="ÈžÀü 56" type="continuous">
    <origin rpy="0 0 0" xyz="0.013 -0.01425 0.004"/>
    <parent link="case5_1"/>
    <child link="link5_1"/>
    <axis xyz="1.0 -0.0 -0.0"/>
  </joint>
  <joint name="°­ÃŒ 57" type="fixed">
    <origin rpy="0 0 0" xyz="0.02625 0.006 0.04565"/>
    <parent link="link5_1"/>
    <child link="case6_1"/>
  </joint>
  <joint name="°­ÃŒ 58" type="fixed">
    <origin rpy="0 0 0" xyz="0.00625 0.0 0.03125"/>
    <parent link="case6_1"/>
    <child link="link6_1"/>
  </joint>
  <joint name="ÈžÀü 59" type="continuous">
    <origin rpy="0 0 0" xyz="-0.008 -0.025 0.03525"/>
    <parent link="case6_1"/>
    <child link="link7_1"/>
    <axis xyz="-0.0 -1.0 -0.0"/>
  </joint>
</robot>
